.E................EEE.
======================================================================
ERROR: test_club_roster (suite.tests.test_qry_club_member.ClubMemberQueryTestCase)
----------------------------------------------------------------------
Traceback (most recent call last):
  File "/home/leo/Projects/ATTEMPT/cse-env/club-suite/clubsuite/suite/tests/test_qry_club_member.py", line 38, in test_club_roster
    club_members=self.clubmanager.club_roster("club")
TypeError: unbound method club_roster() must be called with ClubManager instance as first argument (got str instance instead)

======================================================================
ERROR: test_create_superuser (suite.tests.test_User.UserManagerTestCase)
----------------------------------------------------------------------
Traceback (most recent call last):
  File "/home/leo/Projects/ATTEMPT/cse-env/club-suite/clubsuite/suite/tests/test_User.py", line 73, in test_create_superuser
    user=self.usermanager.create_user(email="test@test.com",password="clubsuite")
  File "/home/leo/Projects/ATTEMPT/cse-env/club-suite/clubsuite/suite/models/mdl_user.py", line 13, in create_user
    **kwargs
TypeError: 'NoneType' object is not callable

======================================================================
ERROR: test_create_user (suite.tests.test_User.UserManagerTestCase)
----------------------------------------------------------------------
Traceback (most recent call last):
  File "/home/leo/Projects/ATTEMPT/cse-env/club-suite/clubsuite/suite/tests/test_User.py", line 68, in test_create_user
    user=self.usermanager.create_user(email="test@test.com",password="clubsuite",first_name="f",last_name="L")
  File "/home/leo/Projects/ATTEMPT/cse-env/club-suite/clubsuite/suite/models/mdl_user.py", line 13, in create_user
    **kwargs
TypeError: 'NoneType' object is not callable

======================================================================
ERROR: test_get_clubs (suite.tests.test_User.UserTestCase)
----------------------------------------------------------------------
Traceback (most recent call last):
  File "/home/leo/Projects/ATTEMPT/cse-env/club-suite/clubsuite/suite/tests/test_User.py", line 44, in test_get_clubs
    self.club._set_owner(officer)
  File "/home/leo/Projects/ATTEMPT/cse-env/club-suite/clubsuite/suite/models/mdl_club.py", line 164, in _set_owner
    user.groups.add(self._get_member_group())
  File "/home/leo/Projects/ATTEMPT/cse-env/club-suite/clubsuite/suite/models/mdl_club.py", line 78, in _get_member_group
    return Group.objects.get(name=self._get_member_group_name())
  File "/home/leo/Projects/ATTEMPT/cse-env/local/lib/python2.7/site-packages/django/db/models/manager.py", line 85, in manager_method
    return getattr(self.get_queryset(), name)(*args, **kwargs)
  File "/home/leo/Projects/ATTEMPT/cse-env/local/lib/python2.7/site-packages/django/db/models/query.py", line 385, in get
    self.model._meta.object_name
DoesNotExist: Group matching query does not exist.

----------------------------------------------------------------------
Ran 22 tests in 1.690s

FAILED (errors=4)
